<!DOCTYPE html>
<html lang="en">
<head>
    <meta charset="UTF-8">
    <meta name="viewport" content="width=device-width, initial-scale=1.0">
    <title>Document</title>
</head>
<body>
    <script>
        //6.Pormise的传透异常？
        //1) 当使用Promise的then链式调用时,可以在最后指定失败的回调，而不用每个then都指定失败的回调
        //@1 什么意思呢？ 旧的是使用回调地狱，每个回调都需要指定失败的回调，而Promise呢？他内部其实也写了 或者默认在每个回调中都指定失败了
                        //只是使用传透异常在最后指定而已 ，不是真的就一下跳到最后去了，而是一个回调一个回调的传到最后去的 是不是很强大
        //@2 前面任何操作出现了异常，都会传到最后指定的失败回调中处理 

        //7.如何中断Promise链？
        //什么意思呢？就是我想在promise链的中间部分给他中断了 不往下执行了
        //这个链 前面说过 下一个执行的条件是上一个执行完了 才开始执行下一个
        //那要是上一个任务一直没有执行完 ，一直没有结果，没有成功也没有失败，那他下一个就不会执行了 (遇事不决，量子力学)
        //想要一个任务一直没结果一直不执行 那就是他不是resolve状态，也不是reject状态，因为这两种状态都有 onResolved和onRejected等着接受呢
        //所以只能是pending状态了 即 返回一个 new Promise(()=>{})

        //(文字表达是不是很抽象，下面通过代码来看看吧)

        new Promise((resolve,reject) => {
            // resolve(1)
            reject(1) //我们把成功的先注释 最后指定的失败的就打印了这个错误 (这里是直接跳到最后去的吗？)
        }).then(
            value => {
                console.log('onResolved1 ', value)
                return 2
            },
            // reason => {throw reason} //关键的来了,这一步我们是可以省略不写的 他默认你写了,这里在干嘛？抛出异常了啊 就是状态是失败的状态
            //他就会往下找失败的回调, 下一个呢、也是默认抛出了异常 和他一样 在最后他找到他的家了 onRejected1
            //这个内部指定的默认的还必须这么写
            //reason => reason 这么写行不行？ 
            //你这么写什么意思 表示这个then返回的promise成功了 只是返回了一个失败的 相当于return Promise.reject(reason) 那他下一步就去找成功的回调了
            // reason => throw reason 那这么写呢？
            // 箭头函数的作用是什么？定义一个匿名函数还有有return的作用 相当于 return throw 是不能return 错误的 
            // 那怎么去除箭头函数 return 的作用呢？ 箭头函数后面紧跟{} ，是函数体的标记

            //那除了这么写还有其他方法吗？ //除了抛出异常 新的promise变为 rejected , reason 抛出的异常
                                        //返回的是另一个新的 promise ，此 promise 的结果就会为新的 promise 的结果
            reason => {return  Promise.reject(reason)}
           //总结一下：.then返回的promise有两种情况会失败 要么抛出异常，要么返回一个失败的Promise
        ).then(
            value => {
                console.log('onResolved2 ', value)
                return 3
                // reason => {throw reason}
                //reason => {return  Promise.reject(reason)}
            }
        ).then(
            value => {
                console.log('onResolved3 ', value)
            }
        ).catch( //这里就是最后指定的失败的回调 
            reason => {
                console.log('onRejected1 ' ,reason)
                return new Promise(() => {}) //返回一个pending状态的promise 就一直是pending状态 下面的会一直等他
            }
        ).then( //此时我不想执行这个then了 上面你啥都不写或者返回个什么 他都会执行 
            value => {
                console.log('onResolved4 ', value)
            },
            reason => {
                console.log('onRejected2 ' ,reason)
            }
        )
    </script>
</body>
</html>